Workbook

Sheet Provider_Data
A1: Provider_ID | B1: Provider_Name | C1: Specialty | D1: Region | E1: Q3_Cost_Per_Episode | F1: Network_Avg_Cost | G1: ER_Visit_Rate | H1: Readmission_Rate | I1: HbA1c_Control_Rate | J1: Preventive_Screen_Rate | K1: Q1_Cost | L1: Q2_Cost | M1: Q3_Cost
A2: P001 | B2: Riverside Medical Group | C2: Primary Care | D2: Midwest | E2: 1240 | F2: 1350 | G2: 0.12 | H2: 0.08 | I2: 0.74 | J2: 0.81 | K2: 1380 | L2: 1290 | M2: 1240
A3: P002 | B3: Lakeview Health Partners | C3: Primary Care | D3: Northeast | E3: 1580 | F3: 1350 | G3: 0.19 | H3: 0.14 | I3: 0.61 | J3: 0.68 | K3: 1490 | L3: 1530 | M3: 1580
A4: P003 | B4: Summit Care Associates | C4: Specialist | D4: South | E4: 2100 | F4: 2200 | G4: 0.09 | H4: 0.06 | I4: 0.82 | J4: 0.88 | K4: 2300 | L4: 2180 | M4: 2100
A5: P004 | B5: Parkview Physician Group | C5: Primary Care | D5: West | E5: 1410 | F5: 1350 | G5: 0.15 | H5: 0.11 | I5: 0.69 | J5: 0.75 | K5: 1440 | L5: 1420 | M5: 1410
A6: P005 | B6: Central Valley Clinic | C6: Specialist | D6: Midwest | E6: 2450 | F6: 2200 | G6: 0.22 | H6: 0.17 | I6: 0.55 | J6: 0.61 | K6: 2200 | L6: 2310 | M6: 2450

Sheet Scorecard
A1: CENTENE PROVIDER NETWORK PERFORMANCE SCORECARD — Q3 2025
A2: Analyst: Sai Tarun Reddy | Data Source: Provider Claims (CMS-modeled) | Network Avg Cost reflects specialty-adjusted baseline
A3: Provider ID | B3: Provider Name | C3: Specialty | D3: Region | E3: Cost vs Network | F3: Cost Rating | G3: ER Visit Rate | H3: ER Rating | I3: HbA1c Control | J3: Quality Rating | K3: QoQ Cost Trend | L3: Overall Rating
A4: =Provider_Data!A2 | B4: =Provider_Data!B2 | C4: =Provider_Data!C2 | D4: =Provider_Data!D2 | E4: =(Provider_Data!F2-Provider_Data!E2)/Provider_Data!F2 | F4: =IF((Provider_Data!F2-Provider_Data!E2)/Provider_Data!F2>=0.05,"Green",IF((Provider_Data!F2-Provider_Data!E2)/Provider_Data!F2<=-0.05,"Red","Amber")) | G4: =Provider_Data!G2 | H4: =IF(Provider_Data!G2<0.13,"Green",IF(Provider_Data!G2<=0.17,"Amber","Red")) | I4: =Provider_Data!I2 | J4: =IF(Provider_Data!I2>0.72,"Green",IF(Provider_Data!I2>=0.65,"Amber","Red")) | K4: =(Provider_Data!M2-Provider_Data!K2)/Provider_Data!K2 | L4: =IF(COUNTIF(F4,"Red")+COUNTIF(H4,"Red")+COUNTIF(J4,"Red")>=2,"Red",IF(COUNTIF(F4,"Green")+COUNTIF(H4,"Green")+COUNTIF(J4,"Green")>=3,"Green","Amber"))
A5: =Provider_Data!A3 | B5: =Provider_Data!B3 | C5: =Provider_Data!C3 | D5: =Provider_Data!D3 | E5: =(Provider_Data!F3-Provider_Data!E3)/Provider_Data!F3 | F5: =IF((Provider_Data!F3-Provider_Data!E3)/Provider_Data!F3>=0.05,"Green",IF((Provider_Data!F3-Provider_Data!E3)/Provider_Data!F3<=-0.05,"Red","Amber")) | G5: =Provider_Data!G3 | H5: =IF(Provider_Data!G3<0.13,"Green",IF(Provider_Data!G3<=0.17,"Amber","Red")) | I5: =Provider_Data!I3 | J5: =IF(Provider_Data!I3>0.72,"Green",IF(Provider_Data!I3>=0.65,"Amber","Red")) | K5: =(Provider_Data!M3-Provider_Data!K3)/Provider_Data!K3 | L5: =IF(COUNTIF(F5,"Red")+COUNTIF(H5,"Red")+COUNTIF(J5,"Red")>=2,"Red",IF(COUNTIF(F5,"Green")+COUNTIF(H5,"Green")+COUNTIF(J5,"Green")>=3,"Green","Amber"))
A6: =Provider_Data!A4 | B6: =Provider_Data!B4 | C6: =Provider_Data!C4 | D6: =Provider_Data!D4 | E6: =(Provider_Data!F4-Provider_Data!E4)/Provider_Data!F4 | F6: =IF((Provider_Data!F4-Provider_Data!E4)/Provider_Data!F4>=0.05,"Green",IF((Provider_Data!F4-Provider_Data!E4)/Provider_Data!F4<=-0.05,"Red","Amber")) | G6: =Provider_Data!G4 | H6: =IF(Provider_Data!G4<0.13,"Green",IF(Provider_Data!G4<=0.17,"Amber","Red")) | I6: =Provider_Data!I4 | J6: =IF(Provider_Data!I4>0.72,"Green",IF(Provider_Data!I4>=0.65,"Amber","Red")) | K6: =(Provider_Data!M4-Provider_Data!K4)/Provider_Data!K4 | L6: =IF(COUNTIF(F6,"Red")+COUNTIF(H6,"Red")+COUNTIF(J6,"Red")>=2,"Red",IF(COUNTIF(F6,"Green")+COUNTIF(H6,"Green")+COUNTIF(J6,"Green")>=3,"Green","Amber"))
A7: =Provider_Data!A5 | B7: =Provider_Data!B5 | C7: =Provider_Data!C5 | D7: =Provider_Data!D5 | E7: =(Provider_Data!F5-Provider_Data!E5)/Provider_Data!F5 | F7: =IF((Provider_Data!F5-Provider_Data!E5)/Provider_Data!F5>=0.05,"Green",IF((Provider_Data!F5-Provider_Data!E5)/Provider_Data!F5<=-0.05,"Red","Amber")) | G7: =Provider_Data!G5 | H7: =IF(Provider_Data!G5<0.13,"Green",IF(Provider_Data!G5<=0.17,"Amber","Red")) | I7: =Provider_Data!I5 | J7: =IF(Provider_Data!I5>0.72,"Green",IF(Provider_Data!I5>=0.65,"Amber","Red")) | K7: =(Provider_Data!M5-Provider_Data!K5)/Provider_Data!K5 | L7: =IF(COUNTIF(F7,"Red")+COUNTIF(H7,"Red")+COUNTIF(J7,"Red")>=2,"Red",IF(COUNTIF(F7,"Green")+COUNTIF(H7,"Green")+COUNTIF(J7,"Green")>=3,"Green","Amber"))
A8: =Provider_Data!A6 | B8: =Provider_Data!B6 | C8: =Provider_Data!C6 | D8: =Provider_Data!D6 | E8: =(Provider_Data!F6-Provider_Data!E6)/Provider_Data!F6 | F8: =IF((Provider_Data!F6-Provider_Data!E6)/Provider_Data!F6>=0.05,"Green",IF((Provider_Data!F6-Provider_Data!E6)/Provider_Data!F6<=-0.05,"Red","Amber")) | G8: =Provider_Data!G6 | H8: =IF(Provider_Data!G6<0.13,"Green",IF(Provider_Data!G6<=0.17,"Amber","Red")) | I8: =Provider_Data!I6 | J8: =IF(Provider_Data!I6>0.72,"Green",IF(Provider_Data!I6>=0.65,"Amber","Red")) | K8: =(Provider_Data!M6-Provider_Data!K6)/Provider_Data!K6 | L8: =IF(COUNTIF(F8,"Red")+COUNTIF(H8,"Red")+COUNTIF(J8,"Red")>=2,"Red",IF(COUNTIF(F8,"Green")+COUNTIF(H8,"Green")+COUNTIF(J8,"Green")>=3,"Green","Amber"))
A10: RATING LEGEND
A11: Green | B11: Performing above target
A12: Amber | B12: Monitor — within tolerance
A13: Red | B13: Action required

Sheet Trend_Chart
A1: PROVIDER COST TREND — Q1 to Q3 2025
A2: Provider | B2: Specialty | C2: Q1 Cost | D2: Q2 Cost | E2: Q3 Cost | F2: QoQ Change
A3: =Provider_Data!B2 | B3: =Provider_Data!C2 | C3: =Provider_Data!K2 | D3: =Provider_Data!L2 | E3: =Provider_Data!M2 | F3: =(Provider_Data!M2-Provider_Data!K2)/Provider_Data!K2
A4: =Provider_Data!B3 | B4: =Provider_Data!C3 | C4: =Provider_Data!K3 | D4: =Provider_Data!L3 | E4: =Provider_Data!M3 | F4: =(Provider_Data!M3-Provider_Data!K3)/Provider_Data!K3
A5: =Provider_Data!B4 | B5: =Provider_Data!C4 | C5: =Provider_Data!K4 | D5: =Provider_Data!L4 | E5: =Provider_Data!M4 | F5: =(Provider_Data!M4-Provider_Data!K4)/Provider_Data!K4
A6: =Provider_Data!B5 | B6: =Provider_Data!C5 | C6: =Provider_Data!K5 | D6: =Provider_Data!L5 | E6: =Provider_Data!M5 | F6: =(Provider_Data!M5-Provider_Data!K5)/Provider_Data!K5
A7: =Provider_Data!B6 | B7: =Provider_Data!C6 | C7: =Provider_Data!K6 | D7: =Provider_Data!L6 | E7: =Provider_Data!M6 | F7: =(Provider_Data!M6-Provider_Data!K6)/Provider_Data!K6

Sheet SQL_Queries
A1: SQL VALIDATION QUERIES — Provider Analytics
A3: Query 1 | B3: Cost Efficiency vs Network Average
A4: SELECT
A5: provider_id,
A6: provider_name,
A7: region,
A8: q3_cost_per_episode,
A9: network_avg_cost,
A10: ROUND((network_avg_cost - q3_cost_per_episode)
A11: / network_avg_cost * 100, 1) AS cost_variance_pct,
A12: CASE
A13: WHEN (network_avg_cost - q3_cost_per_episode)
A14: / network_avg_cost >= 0.05 THEN 'Green'
A15: WHEN (network_avg_cost - q3_cost_per_episode)
... A20: ORDER BY cost_variance_pct DESC;
A22: Query 2 | B22: ER Utilization Root Cause Flag
A23: SELECT
A24: provider_id,
A25: provider_name,
A26: er_visit_rate,
A27: readmission_rate,
A28: CASE
A29: WHEN er_visit_rate > 0.17
A30: AND readmission_rate > 0.13 THEN 'High Risk — Review Contract'
A31: WHEN er_visit_rate > 0.13 THEN 'Monitor — Elevated ER Usage'
A32: ELSE 'Within Target'
A33: END AS utilization_flag
A34: FROM provider_data
A35: ORDER BY er_visit_rate DESC;
A37: Query 3 | B37: Quarter-over-Quarter Cost Trend
A38: SELECT
A39: provider_id,
A40: provider_name,
A41: q1_cost,
A42: q2_cost,
A43: q3_cost,
A44: ROUND((q3_cost - q1_cost) / q1_cost * 100, 1) AS cost_trend_pct,
A45: CASE
A46: WHEN (q3_cost - q1_cost) / q1_cost > 0.05 THEN 'Escalating — Flag for Review'
A47: WHEN (q3_cost - q1_cost) / q1_cost < -0.05 THEN 'Improving'
...

Sheet Executive_Summary
A1: PROVIDER NETWORK PERFORMANCE — FINDINGS MEMO
A2: CONFIDENTIAL — FOR INTERNAL USE ONLY
A3: TO: | B3: Provider Analytics Leadership
A4: FROM: | B4: Sai Tarun Reddy, Data Analyst
A5: DATE: | B5: April 2026
A6: RE: | B6: Provider Network Performance Scorecard — Q3 2025 Sample Analysis
A7: DATA SOURCE: | B7: CMS Medicare-modeled provider claims data. SQL validation queries in SQL_Queries tab.
A9: EXECUTIVE SUMMARY
A10: Summary | B10: This scorecard evaluates 5 providers across four dimensions: cost efficiency vs. network average, ER utilization rate, HbA1c clinical quality, and quarter-over-quarter cost trend. Two providers require immediate action. One is a top performer suitable for network recognition. All findings include data validation flags and recommended next steps.
A12: KEY FINDINGS
A13: P002 — Lakeview Health Partners (RED)
B14: Highest-cost primary care provider at $1,580/episode — 17% above network average. ER visit rate of 0.19 and worsening cost trend across all three quarters (+6.0% Q1 to Q3). Recommend contract review and care management outreach to the patient panel.
A15: P005 — Central Valley Clinic (RED)
B16: Sharpest cost escalation in the cohort (+11.4% Q1 to Q3) and lowest HbA1c control rate at 55%. The combination of rising cost and deteriorating clinical outcomes indicates a gap in chronic disease management. Validate claims data for coding irregularities given the outlier trajectory.
A17: P001 — Riverside Medical Group (GREEN)
B18: Strongest performer — 8.1% below network average cost, improving trend across all three quarters, and above-threshold scores on all four quality indicators. Recommend recognition in next network performance communication and use as a benchmark for peer comparison.
A19: P003 & P004 — Summit Care / Parkview (AMBER)
B20: Both providers are within acceptable tolerance on cost and quality metrics. Summit Care shows a favorable cost trend (-8.7%). Continue monitoring; no action required this quarter.
A22: RECOMMENDED ACTIONS
A23: Action 1 | B23: Flag P002 and P005 for Q4 utilization management review. Escalate to network strategy team.
A24: Action 2 | B24: Run claims data audit on P005 using Query 4 (SQL_Queries tab) to rule out coding irregularities before contract action.
A25: Action 3 | B25: Recognize P001 in next network performance communication. Share benchmark metrics with peer providers.
A26: Action 4 | B26: Establish Q4 baseline targets using this scorecard structure. Automate monthly refresh using SQL queries in appendix.
